[2023-11-21T01:03:54.361+0000] {taskinstance.py:1159} INFO - Dependencies all met for dep_context=non-requeueable deps ti=<TaskInstance: shelter_data_dag.transform_data scheduled__2023-11-01T00:00:00+00:00 [queued]>
[2023-11-21T01:03:54.366+0000] {taskinstance.py:1159} INFO - Dependencies all met for dep_context=requeueable deps ti=<TaskInstance: shelter_data_dag.transform_data scheduled__2023-11-01T00:00:00+00:00 [queued]>
[2023-11-21T01:03:54.367+0000] {taskinstance.py:1361} INFO - Starting attempt 1 of 2
[2023-11-21T01:03:54.374+0000] {taskinstance.py:1382} INFO - Executing <Task(PythonOperator): transform_data> on 2023-11-01 00:00:00+00:00
[2023-11-21T01:03:54.383+0000] {standard_task_runner.py:57} INFO - Started process 258 to run task
[2023-11-21T01:03:54.388+0000] {standard_task_runner.py:84} INFO - Running: ['***', 'tasks', 'run', 'shelter_data_dag', 'transform_data', 'scheduled__2023-11-01T00:00:00+00:00', '--job-id', '233', '--raw', '--subdir', 'DAGS_FOLDER/DAG.py', '--cfg-path', '/tmp/tmpuear4gnm']
[2023-11-21T01:03:54.391+0000] {standard_task_runner.py:85} INFO - Job 233: Subtask transform_data
[2023-11-21T01:03:54.465+0000] {task_command.py:416} INFO - Running <TaskInstance: shelter_data_dag.transform_data scheduled__2023-11-01T00:00:00+00:00 [running]> on host e39dda9a9deb
[2023-11-21T01:03:54.563+0000] {taskinstance.py:1662} INFO - Exporting env vars: AIRFLOW_CTX_DAG_OWNER='***' AIRFLOW_CTX_DAG_ID='shelter_data_dag' AIRFLOW_CTX_TASK_ID='transform_data' AIRFLOW_CTX_EXECUTION_DATE='2023-11-01T00:00:00+00:00' AIRFLOW_CTX_TRY_NUMBER='1' AIRFLOW_CTX_DAG_RUN_ID='scheduled__2023-11-01T00:00:00+00:00'
[2023-11-21T01:03:55.459+0000] {taskinstance.py:1937} ERROR - Task failed with exception
Traceback (most recent call last):
  File "/home/airflow/.local/lib/python3.8/site-packages/airflow/operators/python.py", line 192, in execute
    return_value = self.execute_callable()
  File "/home/airflow/.local/lib/python3.8/site-packages/airflow/operators/python.py", line 209, in execute_callable
    return self.python_callable(*self.op_args, **self.op_kwargs)
  File "/opt/airflow/dags/Scripts/etl.py", line 118, in transform_data
    obj = s3.get_object(Bucket=bucket_name, Key=s3_object_name)
  File "/home/airflow/.local/lib/python3.8/site-packages/botocore/client.py", line 535, in _api_call
    return self._make_api_call(operation_name, kwargs)
  File "/home/airflow/.local/lib/python3.8/site-packages/botocore/client.py", line 980, in _make_api_call
    raise error_class(parsed_response, operation_name)
botocore.errorfactory.NoSuchKey: An error occurred (NoSuchKey) when calling the GetObject operation: The specified key does not exist.
[2023-11-21T01:03:55.493+0000] {taskinstance.py:1400} INFO - Marking task as UP_FOR_RETRY. dag_id=shelter_data_dag, task_id=transform_data, execution_date=20231101T000000, start_date=20231121T010354, end_date=20231121T010355
[2023-11-21T01:03:55.512+0000] {standard_task_runner.py:104} ERROR - Failed to execute job 233 for task transform_data (An error occurred (NoSuchKey) when calling the GetObject operation: The specified key does not exist.; 258)
[2023-11-21T01:03:55.581+0000] {local_task_job_runner.py:228} INFO - Task exited with return code 1
[2023-11-21T01:03:55.636+0000] {taskinstance.py:2778} INFO - 0 downstream tasks scheduled from follow-on schedule check
