[2023-11-21T00:48:42.531+0000] {taskinstance.py:1159} INFO - Dependencies all met for dep_context=non-requeueable deps ti=<TaskInstance: shelter_data_dag.retrieve_data scheduled__2023-11-15T00:00:00+00:00 [queued]>
[2023-11-21T00:48:42.627+0000] {taskinstance.py:1159} INFO - Dependencies all met for dep_context=requeueable deps ti=<TaskInstance: shelter_data_dag.retrieve_data scheduled__2023-11-15T00:00:00+00:00 [queued]>
[2023-11-21T00:48:42.628+0000] {taskinstance.py:1361} INFO - Starting attempt 2 of 2
[2023-11-21T00:48:42.900+0000] {taskinstance.py:1382} INFO - Executing <Task(PythonOperator): retrieve_data> on 2023-11-15 00:00:00+00:00
[2023-11-21T00:48:43.084+0000] {standard_task_runner.py:57} INFO - Started process 265 to run task
[2023-11-21T00:48:43.317+0000] {standard_task_runner.py:84} INFO - Running: ['***', 'tasks', 'run', 'shelter_data_dag', 'retrieve_data', 'scheduled__2023-11-15T00:00:00+00:00', '--job-id', '174', '--raw', '--subdir', 'DAGS_FOLDER/DAG.py', '--cfg-path', '/tmp/tmp6c4t72uh']
[2023-11-21T00:48:43.573+0000] {standard_task_runner.py:85} INFO - Job 174: Subtask retrieve_data
[2023-11-21T00:48:44.318+0000] {task_command.py:416} INFO - Running <TaskInstance: shelter_data_dag.retrieve_data scheduled__2023-11-15T00:00:00+00:00 [running]> on host 51d09cf321f5
[2023-11-21T00:48:44.829+0000] {taskinstance.py:1662} INFO - Exporting env vars: AIRFLOW_CTX_DAG_OWNER='***' AIRFLOW_CTX_DAG_ID='shelter_data_dag' AIRFLOW_CTX_TASK_ID='retrieve_data' AIRFLOW_CTX_EXECUTION_DATE='2023-11-15T00:00:00+00:00' AIRFLOW_CTX_TRY_NUMBER='2' AIRFLOW_CTX_DAG_RUN_ID='scheduled__2023-11-15T00:00:00+00:00'
[2023-11-21T00:49:04.928+0000] {job.py:219} ERROR - Job heartbeat got an exception
Traceback (most recent call last):
  File "/home/airflow/.local/lib/python3.8/site-packages/sqlalchemy/engine/base.py", line 3371, in _wrap_pool_connect
    return fn()
  File "/home/airflow/.local/lib/python3.8/site-packages/sqlalchemy/pool/base.py", line 327, in connect
    return _ConnectionFairy._checkout(self)
  File "/home/airflow/.local/lib/python3.8/site-packages/sqlalchemy/pool/base.py", line 894, in _checkout
    fairy = _ConnectionRecord.checkout(pool)
  File "/home/airflow/.local/lib/python3.8/site-packages/sqlalchemy/pool/base.py", line 493, in checkout
    rec = pool._do_get()
  File "/home/airflow/.local/lib/python3.8/site-packages/sqlalchemy/pool/impl.py", line 256, in _do_get
    return self._create_connection()
  File "/home/airflow/.local/lib/python3.8/site-packages/sqlalchemy/pool/base.py", line 273, in _create_connection
    return _ConnectionRecord(self)
  File "/home/airflow/.local/lib/python3.8/site-packages/sqlalchemy/pool/base.py", line 388, in __init__
    self.__connect()
  File "/home/airflow/.local/lib/python3.8/site-packages/sqlalchemy/pool/base.py", line 691, in __connect
    pool.logger.debug("Error on connect(): %s", e)
  File "/home/airflow/.local/lib/python3.8/site-packages/sqlalchemy/util/langhelpers.py", line 70, in __exit__
    compat.raise_(
  File "/home/airflow/.local/lib/python3.8/site-packages/sqlalchemy/util/compat.py", line 211, in raise_
    raise exception
  File "/home/airflow/.local/lib/python3.8/site-packages/sqlalchemy/pool/base.py", line 686, in __connect
    self.dbapi_connection = connection = pool._invoke_creator(self)
  File "/home/airflow/.local/lib/python3.8/site-packages/sqlalchemy/engine/create.py", line 574, in connect
    return dialect.connect(*cargs, **cparams)
  File "/home/airflow/.local/lib/python3.8/site-packages/sqlalchemy/engine/default.py", line 598, in connect
    return self.dbapi.connect(*cargs, **cparams)
  File "/home/airflow/.local/lib/python3.8/site-packages/psycopg2/__init__.py", line 122, in connect
    conn = _connect(dsn, connection_factory=connection_factory, **kwasync)
psycopg2.OperationalError: could not translate host name "postgres" to address: Temporary failure in name resolution


The above exception was the direct cause of the following exception:

Traceback (most recent call last):
  File "/home/airflow/.local/lib/python3.8/site-packages/airflow/jobs/job.py", line 215, in heartbeat
    heartbeat_callback(session)
  File "/home/airflow/.local/lib/python3.8/site-packages/airflow/utils/session.py", line 76, in wrapper
    return func(*args, **kwargs)
  File "/home/airflow/.local/lib/python3.8/site-packages/airflow/jobs/local_task_job_runner.py", line 246, in heartbeat_callback
    self.task_instance.refresh_from_db()
  File "/home/airflow/.local/lib/python3.8/site-packages/airflow/utils/session.py", line 79, in wrapper
    return func(*args, session=session, **kwargs)
  File "/home/airflow/.local/lib/python3.8/site-packages/airflow/models/taskinstance.py", line 866, in refresh_from_db
    ti = qry.one_or_none()
  File "/home/airflow/.local/lib/python3.8/site-packages/sqlalchemy/orm/query.py", line 2850, in one_or_none
    return self._iter().one_or_none()
  File "/home/airflow/.local/lib/python3.8/site-packages/sqlalchemy/orm/query.py", line 2916, in _iter
    result = self.session.execute(
  File "/home/airflow/.local/lib/python3.8/site-packages/sqlalchemy/orm/session.py", line 1716, in execute
    conn = self._connection_for_bind(bind)
  File "/home/airflow/.local/lib/python3.8/site-packages/sqlalchemy/orm/session.py", line 1555, in _connection_for_bind
    return self._transaction._connection_for_bind(
  File "/home/airflow/.local/lib/python3.8/site-packages/sqlalchemy/orm/session.py", line 750, in _connection_for_bind
    conn = bind.connect()
  File "/home/airflow/.local/lib/python3.8/site-packages/sqlalchemy/future/engine.py", line 406, in connect
    return super(Engine, self).connect()
  File "/home/airflow/.local/lib/python3.8/site-packages/sqlalchemy/engine/base.py", line 3325, in connect
    return self._connection_cls(self, close_with_result=close_with_result)
  File "/home/airflow/.local/lib/python3.8/site-packages/sqlalchemy/engine/base.py", line 96, in __init__
    else engine.raw_connection()
  File "/home/airflow/.local/lib/python3.8/site-packages/sqlalchemy/engine/base.py", line 3404, in raw_connection
    return self._wrap_pool_connect(self.pool.connect, _connection)
  File "/home/airflow/.local/lib/python3.8/site-packages/sqlalchemy/engine/base.py", line 3374, in _wrap_pool_connect
    Connection._handle_dbapi_exception_noconnection(
  File "/home/airflow/.local/lib/python3.8/site-packages/sqlalchemy/engine/base.py", line 2208, in _handle_dbapi_exception_noconnection
    util.raise_(
  File "/home/airflow/.local/lib/python3.8/site-packages/sqlalchemy/util/compat.py", line 211, in raise_
    raise exception
  File "/home/airflow/.local/lib/python3.8/site-packages/sqlalchemy/engine/base.py", line 3371, in _wrap_pool_connect
    return fn()
  File "/home/airflow/.local/lib/python3.8/site-packages/sqlalchemy/pool/base.py", line 327, in connect
    return _ConnectionFairy._checkout(self)
  File "/home/airflow/.local/lib/python3.8/site-packages/sqlalchemy/pool/base.py", line 894, in _checkout
    fairy = _ConnectionRecord.checkout(pool)
  File "/home/airflow/.local/lib/python3.8/site-packages/sqlalchemy/pool/base.py", line 493, in checkout
    rec = pool._do_get()
  File "/home/airflow/.local/lib/python3.8/site-packages/sqlalchemy/pool/impl.py", line 256, in _do_get
    return self._create_connection()
  File "/home/airflow/.local/lib/python3.8/site-packages/sqlalchemy/pool/base.py", line 273, in _create_connection
    return _ConnectionRecord(self)
  File "/home/airflow/.local/lib/python3.8/site-packages/sqlalchemy/pool/base.py", line 388, in __init__
    self.__connect()
  File "/home/airflow/.local/lib/python3.8/site-packages/sqlalchemy/pool/base.py", line 691, in __connect
    pool.logger.debug("Error on connect(): %s", e)
  File "/home/airflow/.local/lib/python3.8/site-packages/sqlalchemy/util/langhelpers.py", line 70, in __exit__
    compat.raise_(
  File "/home/airflow/.local/lib/python3.8/site-packages/sqlalchemy/util/compat.py", line 211, in raise_
    raise exception
  File "/home/airflow/.local/lib/python3.8/site-packages/sqlalchemy/pool/base.py", line 686, in __connect
    self.dbapi_connection = connection = pool._invoke_creator(self)
  File "/home/airflow/.local/lib/python3.8/site-packages/sqlalchemy/engine/create.py", line 574, in connect
    return dialect.connect(*cargs, **cparams)
  File "/home/airflow/.local/lib/python3.8/site-packages/sqlalchemy/engine/default.py", line 598, in connect
    return self.dbapi.connect(*cargs, **cparams)
  File "/home/airflow/.local/lib/python3.8/site-packages/psycopg2/__init__.py", line 122, in connect
    conn = _connect(dsn, connection_factory=connection_factory, **kwasync)
sqlalchemy.exc.OperationalError: (psycopg2.OperationalError) could not translate host name "postgres" to address: Temporary failure in name resolution

(Background on this error at: https://sqlalche.me/e/14/e3q8)
[2023-11-21T00:49:19.861+0000] {etl.py:87} INFO - No new or updated data to upload. Creating an empty CSV with headers.
[2023-11-21T00:49:19.964+0000] {etl.py:91} INFO - Uploading data to 'raw_data'...
[2023-11-21T00:49:20.268+0000] {etl.py:98} INFO - Updating 'Old_Data' with current data...
[2023-11-21T00:49:20.989+0000] {python.py:194} INFO - Done. Returned value was: None
[2023-11-21T00:49:21.106+0000] {taskinstance.py:1400} INFO - Marking task as SUCCESS. dag_id=shelter_data_dag, task_id=retrieve_data, execution_date=20231115T000000, start_date=20231121T004842, end_date=20231121T004921
[2023-11-21T00:49:21.258+0000] {local_task_job_runner.py:228} INFO - Task exited with return code 0
[2023-11-21T00:49:21.360+0000] {taskinstance.py:2778} INFO - 1 downstream tasks scheduled from follow-on schedule check
[2023-11-21T01:04:06.417+0000] {taskinstance.py:1159} INFO - Dependencies all met for dep_context=non-requeueable deps ti=<TaskInstance: shelter_data_dag.retrieve_data scheduled__2023-11-15T00:00:00+00:00 [queued]>
[2023-11-21T01:04:06.427+0000] {taskinstance.py:1159} INFO - Dependencies all met for dep_context=requeueable deps ti=<TaskInstance: shelter_data_dag.retrieve_data scheduled__2023-11-15T00:00:00+00:00 [queued]>
[2023-11-21T01:04:06.427+0000] {taskinstance.py:1361} INFO - Starting attempt 2 of 2
[2023-11-21T01:04:06.459+0000] {taskinstance.py:1382} INFO - Executing <Task(PythonOperator): retrieve_data> on 2023-11-15 00:00:00+00:00
[2023-11-21T01:04:06.468+0000] {standard_task_runner.py:57} INFO - Started process 283 to run task
[2023-11-21T01:04:06.481+0000] {standard_task_runner.py:84} INFO - Running: ['***', 'tasks', 'run', 'shelter_data_dag', 'retrieve_data', 'scheduled__2023-11-15T00:00:00+00:00', '--job-id', '241', '--raw', '--subdir', 'DAGS_FOLDER/DAG.py', '--cfg-path', '/tmp/tmp63vd0vqv']
[2023-11-21T01:04:06.498+0000] {standard_task_runner.py:85} INFO - Job 241: Subtask retrieve_data
[2023-11-21T01:04:06.626+0000] {task_command.py:416} INFO - Running <TaskInstance: shelter_data_dag.retrieve_data scheduled__2023-11-15T00:00:00+00:00 [running]> on host e39dda9a9deb
[2023-11-21T01:04:06.808+0000] {taskinstance.py:1662} INFO - Exporting env vars: AIRFLOW_CTX_DAG_OWNER='***' AIRFLOW_CTX_DAG_ID='shelter_data_dag' AIRFLOW_CTX_TASK_ID='retrieve_data' AIRFLOW_CTX_EXECUTION_DATE='2023-11-15T00:00:00+00:00' AIRFLOW_CTX_TRY_NUMBER='2' AIRFLOW_CTX_DAG_RUN_ID='scheduled__2023-11-15T00:00:00+00:00'
[2023-11-21T01:04:16.444+0000] {etl.py:87} INFO - No new or updated data to upload. Creating an empty CSV with headers.
[2023-11-21T01:04:16.489+0000] {etl.py:91} INFO - Uploading data to 'raw_data'...
[2023-11-21T01:04:16.744+0000] {etl.py:98} INFO - Updating 'Old_Data' with current data...
[2023-11-21T01:04:17.797+0000] {python.py:194} INFO - Done. Returned value was: None
[2023-11-21T01:04:17.893+0000] {taskinstance.py:1400} INFO - Marking task as SUCCESS. dag_id=shelter_data_dag, task_id=retrieve_data, execution_date=20231115T000000, start_date=20231121T010406, end_date=20231121T010417
[2023-11-21T01:04:18.209+0000] {local_task_job_runner.py:228} INFO - Task exited with return code 0
[2023-11-21T01:04:18.348+0000] {taskinstance.py:2778} INFO - 1 downstream tasks scheduled from follow-on schedule check
