[2023-11-21T00:38:39.922+0000] {taskinstance.py:1159} INFO - Dependencies all met for dep_context=non-requeueable deps ti=<TaskInstance: shelter_data_dag.transform_data scheduled__2023-11-12T00:00:00+00:00 [queued]>
[2023-11-21T00:38:39.932+0000] {taskinstance.py:1159} INFO - Dependencies all met for dep_context=requeueable deps ti=<TaskInstance: shelter_data_dag.transform_data scheduled__2023-11-12T00:00:00+00:00 [queued]>
[2023-11-21T00:38:39.933+0000] {taskinstance.py:1361} INFO - Starting attempt 1 of 2
[2023-11-21T00:38:39.956+0000] {taskinstance.py:1382} INFO - Executing <Task(PythonOperator): transform_data> on 2023-11-12 00:00:00+00:00
[2023-11-21T00:38:39.979+0000] {standard_task_runner.py:57} INFO - Started process 64 to run task
[2023-11-21T00:38:39.992+0000] {standard_task_runner.py:84} INFO - Running: ['***', 'tasks', 'run', 'shelter_data_dag', 'transform_data', 'scheduled__2023-11-12T00:00:00+00:00', '--job-id', '110', '--raw', '--subdir', 'DAGS_FOLDER/DAG.py', '--cfg-path', '/tmp/tmp1m08ez21']
[2023-11-21T00:38:40.027+0000] {standard_task_runner.py:85} INFO - Job 110: Subtask transform_data
[2023-11-21T00:38:40.154+0000] {task_command.py:416} INFO - Running <TaskInstance: shelter_data_dag.transform_data scheduled__2023-11-12T00:00:00+00:00 [running]> on host c6d84631e1b9
[2023-11-21T00:38:40.347+0000] {taskinstance.py:1662} INFO - Exporting env vars: AIRFLOW_CTX_DAG_OWNER='***' AIRFLOW_CTX_DAG_ID='shelter_data_dag' AIRFLOW_CTX_TASK_ID='transform_data' AIRFLOW_CTX_EXECUTION_DATE='2023-11-12T00:00:00+00:00' AIRFLOW_CTX_TRY_NUMBER='1' AIRFLOW_CTX_DAG_RUN_ID='scheduled__2023-11-12T00:00:00+00:00'
[2023-11-21T00:38:41.295+0000] {taskinstance.py:1937} ERROR - Task failed with exception
Traceback (most recent call last):
  File "/home/airflow/.local/lib/python3.8/site-packages/airflow/operators/python.py", line 192, in execute
    return_value = self.execute_callable()
  File "/home/airflow/.local/lib/python3.8/site-packages/airflow/operators/python.py", line 209, in execute_callable
    return self.python_callable(*self.op_args, **self.op_kwargs)
  File "/opt/airflow/dags/Scripts/etl.py", line 118, in transform_data
    obj = s3.get_object(Bucket=bucket_name, Key=s3_object_name)
  File "/home/airflow/.local/lib/python3.8/site-packages/botocore/client.py", line 535, in _api_call
    return self._make_api_call(operation_name, kwargs)
  File "/home/airflow/.local/lib/python3.8/site-packages/botocore/client.py", line 980, in _make_api_call
    raise error_class(parsed_response, operation_name)
botocore.errorfactory.NoSuchKey: An error occurred (NoSuchKey) when calling the GetObject operation: The specified key does not exist.
[2023-11-21T00:38:41.326+0000] {taskinstance.py:1400} INFO - Marking task as UP_FOR_RETRY. dag_id=shelter_data_dag, task_id=transform_data, execution_date=20231112T000000, start_date=20231121T003839, end_date=20231121T003841
[2023-11-21T00:38:41.372+0000] {standard_task_runner.py:104} ERROR - Failed to execute job 110 for task transform_data (An error occurred (NoSuchKey) when calling the GetObject operation: The specified key does not exist.; 64)
[2023-11-21T00:38:41.415+0000] {local_task_job_runner.py:228} INFO - Task exited with return code 1
[2023-11-21T00:38:41.520+0000] {taskinstance.py:2778} INFO - 0 downstream tasks scheduled from follow-on schedule check
[2023-11-21T00:49:19.682+0000] {taskinstance.py:1159} INFO - Dependencies all met for dep_context=non-requeueable deps ti=<TaskInstance: shelter_data_dag.transform_data scheduled__2023-11-12T00:00:00+00:00 [queued]>
[2023-11-21T00:49:19.746+0000] {taskinstance.py:1159} INFO - Dependencies all met for dep_context=requeueable deps ti=<TaskInstance: shelter_data_dag.transform_data scheduled__2023-11-12T00:00:00+00:00 [queued]>
[2023-11-21T00:49:19.749+0000] {taskinstance.py:1361} INFO - Starting attempt 1 of 2
[2023-11-21T00:49:19.891+0000] {taskinstance.py:1382} INFO - Executing <Task(PythonOperator): transform_data> on 2023-11-12 00:00:00+00:00
[2023-11-21T00:49:20.108+0000] {standard_task_runner.py:57} INFO - Started process 277 to run task
[2023-11-21T00:49:20.150+0000] {standard_task_runner.py:84} INFO - Running: ['***', 'tasks', 'run', 'shelter_data_dag', 'transform_data', 'scheduled__2023-11-12T00:00:00+00:00', '--job-id', '176', '--raw', '--subdir', 'DAGS_FOLDER/DAG.py', '--cfg-path', '/tmp/tmps8pky4jz']
[2023-11-21T00:49:20.189+0000] {standard_task_runner.py:85} INFO - Job 176: Subtask transform_data
[2023-11-21T00:49:20.832+0000] {task_command.py:416} INFO - Running <TaskInstance: shelter_data_dag.transform_data scheduled__2023-11-12T00:00:00+00:00 [running]> on host 51d09cf321f5
[2023-11-21T00:49:21.126+0000] {taskinstance.py:1662} INFO - Exporting env vars: AIRFLOW_CTX_DAG_OWNER='***' AIRFLOW_CTX_DAG_ID='shelter_data_dag' AIRFLOW_CTX_TASK_ID='transform_data' AIRFLOW_CTX_EXECUTION_DATE='2023-11-12T00:00:00+00:00' AIRFLOW_CTX_TRY_NUMBER='1' AIRFLOW_CTX_DAG_RUN_ID='scheduled__2023-11-12T00:00:00+00:00'
[2023-11-21T00:49:23.490+0000] {python.py:194} INFO - Done. Returned value was: None
[2023-11-21T00:49:23.578+0000] {taskinstance.py:1400} INFO - Marking task as SUCCESS. dag_id=shelter_data_dag, task_id=transform_data, execution_date=20231112T000000, start_date=20231121T004919, end_date=20231121T004923
[2023-11-21T00:49:23.660+0000] {local_task_job_runner.py:228} INFO - Task exited with return code 0
[2023-11-21T00:49:23.803+0000] {taskinstance.py:2778} INFO - 1 downstream tasks scheduled from follow-on schedule check
[2023-11-21T01:03:58.213+0000] {taskinstance.py:1159} INFO - Dependencies all met for dep_context=non-requeueable deps ti=<TaskInstance: shelter_data_dag.transform_data scheduled__2023-11-12T00:00:00+00:00 [queued]>
[2023-11-21T01:03:58.218+0000] {taskinstance.py:1159} INFO - Dependencies all met for dep_context=requeueable deps ti=<TaskInstance: shelter_data_dag.transform_data scheduled__2023-11-12T00:00:00+00:00 [queued]>
[2023-11-21T01:03:58.219+0000] {taskinstance.py:1361} INFO - Starting attempt 1 of 2
[2023-11-21T01:03:58.224+0000] {taskinstance.py:1382} INFO - Executing <Task(PythonOperator): transform_data> on 2023-11-12 00:00:00+00:00
[2023-11-21T01:03:58.233+0000] {standard_task_runner.py:57} INFO - Started process 264 to run task
[2023-11-21T01:03:58.236+0000] {standard_task_runner.py:84} INFO - Running: ['***', 'tasks', 'run', 'shelter_data_dag', 'transform_data', 'scheduled__2023-11-12T00:00:00+00:00', '--job-id', '235', '--raw', '--subdir', 'DAGS_FOLDER/DAG.py', '--cfg-path', '/tmp/tmpgx3zvy9p']
[2023-11-21T01:03:58.238+0000] {standard_task_runner.py:85} INFO - Job 235: Subtask transform_data
[2023-11-21T01:03:58.287+0000] {task_command.py:416} INFO - Running <TaskInstance: shelter_data_dag.transform_data scheduled__2023-11-12T00:00:00+00:00 [running]> on host e39dda9a9deb
[2023-11-21T01:03:58.432+0000] {taskinstance.py:1662} INFO - Exporting env vars: AIRFLOW_CTX_DAG_OWNER='***' AIRFLOW_CTX_DAG_ID='shelter_data_dag' AIRFLOW_CTX_TASK_ID='transform_data' AIRFLOW_CTX_EXECUTION_DATE='2023-11-12T00:00:00+00:00' AIRFLOW_CTX_TRY_NUMBER='1' AIRFLOW_CTX_DAG_RUN_ID='scheduled__2023-11-12T00:00:00+00:00'
[2023-11-21T01:03:59.261+0000] {taskinstance.py:1937} ERROR - Task failed with exception
Traceback (most recent call last):
  File "/home/airflow/.local/lib/python3.8/site-packages/airflow/operators/python.py", line 192, in execute
    return_value = self.execute_callable()
  File "/home/airflow/.local/lib/python3.8/site-packages/airflow/operators/python.py", line 209, in execute_callable
    return self.python_callable(*self.op_args, **self.op_kwargs)
  File "/opt/airflow/dags/Scripts/etl.py", line 118, in transform_data
    obj = s3.get_object(Bucket=bucket_name, Key=s3_object_name)
  File "/home/airflow/.local/lib/python3.8/site-packages/botocore/client.py", line 535, in _api_call
    return self._make_api_call(operation_name, kwargs)
  File "/home/airflow/.local/lib/python3.8/site-packages/botocore/client.py", line 980, in _make_api_call
    raise error_class(parsed_response, operation_name)
botocore.errorfactory.NoSuchKey: An error occurred (NoSuchKey) when calling the GetObject operation: The specified key does not exist.
[2023-11-21T01:03:59.308+0000] {taskinstance.py:1400} INFO - Marking task as UP_FOR_RETRY. dag_id=shelter_data_dag, task_id=transform_data, execution_date=20231112T000000, start_date=20231121T010358, end_date=20231121T010359
[2023-11-21T01:03:59.324+0000] {standard_task_runner.py:104} ERROR - Failed to execute job 235 for task transform_data (An error occurred (NoSuchKey) when calling the GetObject operation: The specified key does not exist.; 264)
[2023-11-21T01:03:59.385+0000] {local_task_job_runner.py:228} INFO - Task exited with return code 1
[2023-11-21T01:03:59.459+0000] {taskinstance.py:2778} INFO - 0 downstream tasks scheduled from follow-on schedule check
